#VRML_SIM R2025a utf8

EXTERNPROTO "https://raw.githubusercontent.com/cyberbotics/webots/R2025a/projects/objects/backgrounds/protos/TexturedBackground.proto"
EXTERNPROTO "https://raw.githubusercontent.com/cyberbotics/webots/R2025a/projects/objects/backgrounds/protos/TexturedBackgroundLight.proto"
EXTERNPROTO "https://raw.githubusercontent.com/cyberbotics/webots/R2025a/projects/objects/floors/protos/RectangleArena.proto"
EXTERNPROTO "https://raw.githubusercontent.com/cyberbotics/webots/R2025a/projects/appearances/protos/Asphalt.proto"

WorldInfo {
}
Viewpoint {
  orientation -0.11867030791568937 -0.2605294320376339 -0.9581449645337303 4.295127599824211
  position 0.2868526818597086 -1.5441152933009754 0.2628197454863801
}
TexturedBackground {
}
TexturedBackgroundLight {
}
RectangleArena {
  floorSize 3 2
  wallHeight 0.07
}
Robot {
  translation 1.504827804011817 -2.1842641642561493 0.02665624298523911
  rotation 0.000984265904691172 -0.001356658926545459 0.9999985953476064 -2.6751207027004154
  children [
    DEF CORPS_DEPLACE Pose {
      translation 0 0 0.22
      children [
        DEF CORPS_SHAPE Shape {
          appearance PBRAppearance {
            baseColor 0 0 0
            roughness 0.5
            metalness 0
          }
          geometry Box {
            size 0.3 0.4 0.375
          }
        }
      ]
    }
    DEF WHEEL_A_WRAPPER Pose {
      rotation 0 0 1 -1.0472
      children [
        DEF WHEEL_A_RADIUS Pose {
          translation 0 0.2 0
          children [
            HingeJoint {
              jointParameters HingeJointParameters {
                position -53.01471861490622
                axis 0 1 0
              }
              device [
                RotationalMotor {
                  name "motor1"
                  maxVelocity 20
                }
                PositionSensor {
                  name "encoder1"
                }
              ]
              endPoint Solid {
                translation 0.003499013375436684 0.0013527191834031812 0.0005367668511421413
                rotation -0.007181787203856427 -0.9999681543127564 0.003480271957479086 1.1831162532181438
                children [
                  DEF VISUAL_WHEEL_1 Transform {
                    rotation 0 0 1 -1.57
                    scale 0.001 0.001 0.001
                    children [
                      Shape {
                        appearance PBRAppearance {
                          baseColor 0.1 0.1 0.1
                          transparency 1
                          roughness 0.8
                        }
                        geometry Mesh {
                          url [
                            "../protos/meshes/roue.stl"
                          ]
                        }
                      }
                    ]
                  }
                  DEF ROUE_COLLISION Pose {
                    rotation 1 0 0 1.5708
                    children [
                      Shape {
                        appearance PBRAppearance {
                          baseColor 0.1 0.1 0.1
                          transparency 1
                          roughness 0.8
                          metalness 0
                        }
                        geometry Cylinder {
                          height 0.02
                          radius 0.03
                        }
                      }
                    ]
                  }
                ]
                name "wheel_solid_1"
                boundingObject USE ROUE_COLLISION
                physics Physics {
                  mass 0.2
                }
                linearVelocity -5.09528080029894e-10 -7.270953811342615e-10 4.11279468792695e-07
                angularVelocity -1.3263004481428217e-09 -1.088915114877675e-09 -1.0513030520687241e-10
              }
            }
          ]
        }
      ]
    }
    DEF WHEEL_B_WRAPPER Pose {
      rotation 0 0 1 1.0472
      children [
        DEF WHEEL_B_RADIUS Pose {
          translation 0 0.2 0
          children [
            HingeJoint {
              jointParameters HingeJointParameters {
                position 521.768946487222
                axis 0 1 0
              }
              device [
                RotationalMotor {
                  name "motor2"
                  maxVelocity 20
                }
                PositionSensor {
                  name "encoder2"
                }
              ]
              endPoint Solid {
                translation -0.0032326973839032825 -0.00016166613624468573 0.0010108696970169797
                rotation -0.007977696583934313 -0.9999600369135957 0.0040349638133283915 5.485185799536974
                children [
                  DEF VISUAL_WHEEL_2 Transform {
                    rotation 0 0 1 -1.57
                    scale 0.001 0.001 0.001
                    children [
                      Shape {
                        appearance PBRAppearance {
                          baseColor 0.1 0.1 0.1
                          transparency 1
                          roughness 0.8
                        }
                        geometry Mesh {
                          url [
                            "../protos/meshes/roue.stl"
                          ]
                        }
                      }
                    ]
                  }
                  USE ROUE_COLLISION
                ]
                name "wheel_solid_2"
                boundingObject USE ROUE_COLLISION
                physics Physics {
                  mass 0.2
                }
                linearVelocity 5.104025795453558e-12 5.015001426612027e-10 4.059978346759544e-07
                angularVelocity 1.9426606037199958e-10 1.8144739450902134e-10 -1.0342807590203343e-10
              }
            }
          ]
        }
      ]
    }
    DEF WHEEL_C_WRAPPER Pose {
      rotation 0 0 1 3.14159
      children [
        DEF WHEEL_C_RADIUS Pose {
          translation 0 0.2 0
          children [
            HingeJoint {
              jointParameters HingeJointParameters {
                position 701.5947793304973
                axis 0 1 0
              }
              device [
                RotationalMotor {
                  name "motor3"
                  maxVelocity 20
                }
                PositionSensor {
                  name "encoder3"
                }
              ]
              endPoint Solid {
                translation 0.004764112233164467 0.0008889910574271258 -8.178330990136953e-06
                rotation 0.0044043456627208405 0.99998635008515 -0.002810939818435633 4.290553363648748
                children [
                  DEF VISUAL_WHEEL_3 Transform {
                    rotation 0 0 1 -1.57
                    scale 0.001 0.001 0.001
                    children [
                      Shape {
                        appearance PBRAppearance {
                          baseColor 0.1 0.1 0.1
                          transparency 1
                          roughness 0.8
                        }
                        geometry Mesh {
                          url [
                            "../protos/meshes/roue.stl"
                          ]
                        }
                      }
                    ]
                  }
                  USE ROUE_COLLISION
                ]
                name "wheel_solid_3"
                boundingObject USE ROUE_COLLISION
                physics Physics {
                  mass 0.2
                }
                linearVelocity 4.935128463821779e-10 2.4824260590659433e-10 3.9217782450865546e-07
                angularVelocity 3.775551860853681e-10 5.439899933497683e-10 -1.0071235257649517e-10
              }
            }
          ]
        }
      ]
    }
  ]
  name "robot secours"
  boundingObject USE CORPS_DEPLACE
  physics Physics {
    density -1
    mass 10
  }
  controller "<none>"
  linearVelocity 2.0748857011698478e-11 -3.388025849870923e-11 -1.6528857486263462e-09
  angularVelocity 1.87293122024687e-10 1.1153084365076642e-10 -1.0686079752537938e-10
}
DEF ROBOT_2 Robot {
  translation -1.0640017190037427 0.4620435631603715 0.028621461824618624
  rotation 4.637576111268581e-08 7.145718070447632e-08 -0.9999999999999963 -2.764838450507821
  children [
    DEF CORPS_PRINCIPAL Pose {
      translation 6.60597e-08 3.10842e-07 -0.01
      rotation -0.7745972141184518 0.44721212362085194 0.44721412362140484 -1.823475307179586
      children [
        Transform {
          scale 0.001 0.001 0.001
          children [
            Shape {
              appearance PBRAppearance {
                baseColor 0 0.2 0.8
                roughness 0.5
                metalness 0
              }
              geometry Mesh {
                url [
                  "../protos/meshes/base_link.stl"
                ]
              }
              castShadows FALSE
            }
          ]
        }
      ]
    }
    DEF WHEEL_A_WRAPPER Pose {
      rotation 0 0 1 -1.0472
      children [
        DEF WHEEL_A_RADIUS Pose {
          translation 0 0.1569 0
          children [
            HingeJoint {
              jointParameters HingeJointParameters {
                position 17.0142601498946
                axis 0 1 0
              }
              device [
                RotationalMotor {
                  name "motor1"
                  maxVelocity 20
                }
                PositionSensor {
                  name "encoder1"
                }
              ]
              endPoint Solid {
                rotation -0.0920006143808223 -0.7041066129638635 0.7041091992966059 3.3250766969965286
                children [
                  DEF ROUE_VISUEL Shape {
                    appearance Asphalt {
                    }
                    geometry Cylinder {
                      height 0.02
                      radius 0.03
                    }
                  }
                ]
                name "wheel_solid_1"
                boundingObject USE ROUE_VISUEL
                physics Physics {
                }
                linearVelocity -0.0033508474164395123 0.021972086085107145 1.8018903711828532e-09
                angularVelocity -0.776679641191583 -0.11670609811643619 -0.1420616167651345
              }
            }
          ]
        }
      ]
    }
    DEF WHEEL_B_WRAPPER Pose {
      rotation 0 0 1 1.0472
      children [
        DEF WHEEL_B_RADIUS Pose {
          translation 0 0.1569 0
          children [
            HingeJoint {
              jointParameters HingeJointParameters {
                position 590.3261425828271
                axis 0 1 0
              }
              device [
                RotationalMotor {
                  name "motor2"
                  maxVelocity 20
                }
                PositionSensor {
                  name "encoder2"
                }
              ]
              endPoint Solid {
                rotation 0.9788741130611164 -0.14457751764857185 0.14457804871206995 1.5921506088616613
                children [
                  USE ROUE_VISUEL
                ]
                name "wheel_solid_2"
                boundingObject USE ROUE_VISUEL
                physics Physics {
                }
                linearVelocity -0.01744984052538893 -0.0139035484908135 -3.5387344568407704e-09
                angularVelocity 0.48941370707236115 -0.6142691058149591 -0.1420615640170666
              }
            }
          ]
        }
      ]
    }
    DEF WHEEL_C_WRAPPER Pose {
      rotation 0 0 1 3.14159
      children [
        DEF WHEEL_C_RADIUS Pose {
          translation 0 0.1569 0
          children [
            HingeJoint {
              jointParameters HingeJointParameters {
                position 766.9604121483075
                axis 0 1 0
              }
              device [
                RotationalMotor {
                  name "motor3"
                  maxVelocity 20
                }
                PositionSensor {
                  name "encoder3"
                }
              ]
              endPoint Solid {
                rotation 0.9590383284181149 0.20030625285654677 -0.200306988623855 1.6126120463229765
                children [
                  USE ROUE_VISUEL
                ]
                name "wheel_solid_3"
                boundingObject USE ROUE_VISUEL
                physics Physics {
                }
                linearVelocity 0.020672512116521345 -0.008175369415862303 1.7335530204015994e-09
                angularVelocity 0.2872694169938751 0.7309770833523448 -0.1420614459889845
              }
            }
          ]
        }
      ]
    }
  ]
  name "RobotOmniTriangle"
  boundingObject Pose {
    translation 0 0 0.05
    children [
      Box {
        size 0.3 0.3 0.1
      }
    ]
  }
  physics Physics {
    density -1
    mass 5
  }
  controller "teensy_controller"
  linearVelocity -4.274749455019081e-05 -3.558084956090007e-05 -1.1014435586066727e-12
  angularVelocity 1.7829485103202954e-08 1.4530763034392994e-08 -0.1418410688933237
}
