#VRML_SIM R2025a utf8

EXTERNPROTO "https://raw.githubusercontent.com/cyberbotics/webots/R2025a/projects/objects/backgrounds/protos/TexturedBackground.proto"
EXTERNPROTO "https://raw.githubusercontent.com/cyberbotics/webots/R2025a/projects/objects/backgrounds/protos/TexturedBackgroundLight.proto"
EXTERNPROTO "https://raw.githubusercontent.com/cyberbotics/webots/R2025a/projects/objects/floors/protos/RectangleArena.proto"
EXTERNPROTO "https://raw.githubusercontent.com/cyberbotics/webots/R2025a/projects/appearances/protos/Asphalt.proto"

WorldInfo {
}
Viewpoint {
  orientation 0.05439636709449205 0.18719040814764543 -0.9808163876814249 0.5760368468794441
  position -0.765313781604235 0.7198708249631676 0.20340504316006408
}
TexturedBackground {
}
TexturedBackgroundLight {
}
RectangleArena {
  floorSize 3 2
  wallHeight 0.07
}
Robot {
  translation -0.3629269887711747 -0.35989924657899675 0.02728730067876825
  rotation -2.3805514764243777e-08 -1.2491394867363944e-08 0.9999999999999996 2.0798965047311215
  children [
    DEF CORPS_DEPLACE Pose {
      translation 0 0 0.22
      children [
        DEF CORPS_SHAPE Shape {
          appearance PBRAppearance {
            baseColor 0 0 0
            roughness 0.5
            metalness 0
          }
          geometry Box {
            size 0.3 0.4 0.375
          }
        }
      ]
    }
    DEF WHEEL_A_WRAPPER Pose {
      rotation 0 0 1 -1.0472
      children [
        DEF WHEEL_A_RADIUS Pose {
          translation 0 0.2 0
          children [
            HingeJoint {
              jointParameters HingeJointParameters {
                position -19.18617703595721
                axis 0 1 0
              }
              device [
                RotationalMotor {
                  name "motor1"
                  maxVelocity 20
                }
                PositionSensor {
                  name "encoder1"
                }
              ]
              endPoint Solid {
                rotation -0.9723210594375992 0.16521434085366646 -0.1652149477209411 4.6843197727708965
                children [
                  DEF ROUE_VISUEL Shape {
                    appearance Asphalt {
                    }
                    geometry Cylinder {
                      height 0.02
                      radius 0.03
                    }
                  }
                ]
                name "wheel_solid_1"
                boundingObject USE ROUE_VISUEL
                physics Physics {
                }
                linearVelocity 2.3588671609293395e-13 2.8487091849901465e-13 4.0434015502422404e-07
                angularVelocity -1.2065342750317823e-11 6.981439607216892e-12 -4.815804908976055e-13
              }
            }
          ]
        }
      ]
    }
    DEF WHEEL_B_WRAPPER Pose {
      rotation 0 0 1 1.0472
      children [
        DEF WHEEL_B_RADIUS Pose {
          translation 0 0.2 0
          children [
            HingeJoint {
              jointParameters HingeJointParameters {
                position 44.6776802381991
                axis 0 1 0
              }
              device [
                RotationalMotor {
                  name "motor2"
                  maxVelocity 20
                }
                PositionSensor {
                  name "encoder2"
                }
              ]
              endPoint Solid {
                rotation -0.8899221378759307 -0.32251963068155065 0.32252081536448024 4.596027483013699
                children [
                  USE ROUE_VISUEL
                ]
                name "wheel_solid_2"
                boundingObject USE ROUE_VISUEL
                physics Physics {
                }
                linearVelocity 2.6525319415727324e-13 1.5329826592043198e-14 4.043388804149337e-07
                angularVelocity 6.097659576669105e-13 1.1131899263907518e-11 -4.806608300819795e-13
              }
            }
          ]
        }
      ]
    }
    DEF WHEEL_C_WRAPPER Pose {
      rotation 0 0 1 3.14159
      children [
        DEF WHEEL_C_RADIUS Pose {
          translation 0 0.2 0
          children [
            HingeJoint {
              jointParameters HingeJointParameters {
                position 70.2135431728882
                axis 0 1 0
              }
              device [
                RotationalMotor {
                  name "motor3"
                  maxVelocity 20
                }
                PositionSensor {
                  name "encoder3"
                }
              ]
              endPoint Solid {
                rotation -0.7560858177721559 -0.46278108366932463 0.46278278356228386 4.436358455357224
                children [
                  USE ROUE_VISUEL
                ]
                name "wheel_solid_3"
                boundingObject USE ROUE_VISUEL
                physics Physics {
                }
                linearVelocity 1.3956680970734847e-13 -1.3946153703450734e-13 4.043377988065061e-07
                angularVelocity 6.1391088795947155e-12 3.1591089846933036e-12 -4.805671173701094e-13
              }
            }
          ]
        }
      ]
    }
  ]
  name "cdr"
  boundingObject USE CORPS_DEPLACE
  physics Physics {
    density -1
    mass 10
  }
  controller "<none>"
  linearVelocity 1.6312620367030164e-13 4.014182737673869e-14 -4.674073807109434e-10
  angularVelocity 6.113874548655712e-14 -2.2584695564818965e-13 -4.806392820658863e-13
}
DEF ROBOT_2 Robot {
  translation -0.1879557735806065 0.4974286677684216 0.0260037605837524
  rotation 0.04394233714877695 0.005470088248379557 -0.9990190934814299 2.330857674933964
  children [
    Transform {
      scale 0.001 0.001 0.001
      children [
        Shape {
          appearance PBRAppearance {
            baseColor 0 0.2 0.8
            roughness 0.5
            metalness 0
          }
          geometry Mesh {
            url [
              "../protos/meshes/base_link.stl"
            ]
          }
          castShadows FALSE
        }
      ]
    }
    DEF ROUE_1_WRAPPER Pose {
      rotation 0 0 1 -1.0472
      children [
        Pose {
          translation 0 0.2 0
          children [
            HingeJoint {
              jointParameters HingeJointParameters {
                position 19.79518403505203
                axis 0 1 0
              }
              device [
                RotationalMotor {
                  name "motor1"
                  maxVelocity 20
                }
                PositionSensor {
                  name "encoder1"
                }
              ]
              endPoint Solid {
                translation 0.008882960903167978 0.0005151193999379592 0.006923049726363807
                rotation 0.4153288578056473 0.41288572204136537 0.810572217885758 1.7816972239018114
                children [
                  DEF VISUAL_WHEEL_1 Transform {
                    rotation 0 0 1 -1.57
                    scale 0.001 0.001 0.001
                    children [
                      Shape {
                        appearance PBRAppearance {
                          baseColor 0.1 0.1 0.1
                          roughness 0.8
                        }
                        geometry Mesh {
                          url [
                            "../protos/meshes/roue.stl"
                          ]
                        }
                      }
                    ]
                  }
                ]
                name "wheel_solid_1"
                boundingObject Pose {
                  rotation 1 0 0 1.5708
                  children [
                    Cylinder {
                      height 0.02
                      radius 0.03
                    }
                  ]
                }
                physics Physics {
                  mass 0.2
                }
                linearVelocity -0.14054105171108053 0.04369810955989987 -0.0789557690981034
                angularVelocity -1.0766348896989104 -5.080412516957727 -0.939071925275877
              }
            }
          ]
        }
      ]
    }
    DEF ROUE_2_WRAPPER Pose {
      rotation 0 0 1 1.0472
      children [
        Pose {
          translation 0 0.2 0
          children [
            HingeJoint {
              jointParameters HingeJointParameters {
                position 19.796138394669548
                axis 0 1 0
              }
              device [
                RotationalMotor {
                  name "motor2"
                  maxVelocity 20
                }
                PositionSensor {
                  name "encoder2"
                }
              ]
              endPoint Solid {
                translation 0.0004958286018585419 -0.005517414482112849 0.0005333111821480905
                rotation 0.41310446607816936 0.41584829957228425 0.8101943543675865 1.7818142127229741
                children [
                  DEF VISUAL_WHEEL_2 Transform {
                    translation 0.080024 -0.0299363 0
                    rotation 0 0 1 -1.57
                    scale 0.001 0.001 0.001
                    children [
                      Shape {
                        appearance PBRAppearance {
                          baseColor 0.1 0.1 0.1
                          roughness 0.8
                        }
                        geometry Mesh {
                          url [
                            "../protos/meshes/roue.stl"
                          ]
                        }
                      }
                    ]
                  }
                ]
                name "wheel_solid_2"
                boundingObject Pose {
                  translation 0.080024 -0.0299363 0
                  rotation 1 0 0 1.5708
                  children [
                    Cylinder {
                      height 0.02
                      radius 0.03
                    }
                  ]
                }
                physics Physics {
                  mass 0.2
                }
                linearVelocity 0.031213490945169238 -0.06017492833360329 -0.06753877792881233
                angularVelocity 4.776792036528464 1.2526365985862693 -0.279113285908716
              }
            }
          ]
        }
      ]
    }
    DEF ROUE_3_WRAPPER Pose {
      rotation 0 0 1 3.14159
      children [
        Pose {
          translation 0 0.2 0
          children [
            HingeJoint {
              jointParameters HingeJointParameters {
                position 19.79576521919437
                axis 0 1 0
              }
              device [
                RotationalMotor {
                  name "motor3"
                  maxVelocity 20
                }
                PositionSensor {
                  name "encoder3"
                }
              ]
              endPoint Solid {
                translation 0.000778141308755957 0.0005737255185149781 0.0020992818374732016
                rotation -0.4118356639436848 -0.4173320429347267 -0.8100773739859617 4.5029216682295985
                children [
                  DEF VISUAL_WHEEL_3 Transform {
                    rotation 0 0 1 -1.57
                    scale 0.001 0.001 0.001
                    children [
                      Shape {
                        appearance PBRAppearance {
                          baseColor 0.1 0.1 0.1
                          roughness 0.8
                        }
                        geometry Mesh {
                          url [
                            "../protos/meshes/roue.stl"
                          ]
                        }
                      }
                    ]
                  }
                ]
                name "wheel_solid_3"
                boundingObject Pose {
                  rotation 1 0 0 1.5708
                  children [
                    Cylinder {
                      height 0.02
                      radius 0.03
                    }
                  ]
                }
                physics Physics {
                  mass 0.2
                }
                linearVelocity 0.1151617258225123 0.1006989970411419 -0.05300214294387065
                angularVelocity -3.6638564022727667 3.1827747339039094 -0.7603033903812209
              }
            }
          ]
        }
      ]
    }
  ]
  name "RobotOmniTriangle"
  boundingObject Pose {
    translation 0 0 0.05
    children [
      Box {
        size 0.3 0.3 0.1
      }
    ]
  }
  physics Physics {
    density -1
    mass 5
  }
  controller "test_holonome"
  linearVelocity 0.0077235825047228665 0.0003509542618375487 -0.022618901717794893
  angularVelocity 0.008376447189782574 -0.20866332473155347 -0.6386250935413449
}
