#VRML_SIM R2025a utf8

EXTERNPROTO "https://raw.githubusercontent.com/cyberbotics/webots/R2025a/projects/objects/backgrounds/protos/TexturedBackground.proto"
EXTERNPROTO "https://raw.githubusercontent.com/cyberbotics/webots/R2025a/projects/objects/backgrounds/protos/TexturedBackgroundLight.proto"
EXTERNPROTO "https://raw.githubusercontent.com/cyberbotics/webots/R2025a/projects/objects/floors/protos/RectangleArena.proto"
EXTERNPROTO "https://raw.githubusercontent.com/cyberbotics/webots/R2025a/projects/appearances/protos/Asphalt.proto"

WorldInfo {
}
Viewpoint {
  orientation -0.38657882776515246 0.5348740739501207 0.7513098794370545 1.2354097082423097
  position -1.1646757267001104 -1.9570146246799398 2.4856926699966126
}
TexturedBackground {
}
TexturedBackgroundLight {
}
RectangleArena {
  floorSize 3 2
  wallHeight 0.07
}
Robot {
  translation -0.362926988777682 -0.3598992465785735 0.027287300678768
  rotation -2.380551284546746e-08 -1.2491390994958435e-08 0.9999999999999996 2.079896504731125
  children [
    DEF CORPS_DEPLACE Pose {
      translation 0 0 0.22
      children [
        DEF CORPS_SHAPE Shape {
          appearance PBRAppearance {
            baseColor 0 0 0
            roughness 0.5
            metalness 0
          }
          geometry Box {
            size 0.3 0.4 0.375
          }
        }
      ]
    }
    DEF WHEEL_A_WRAPPER Pose {
      rotation 0 0 1 -1.0472
      children [
        DEF WHEEL_A_RADIUS Pose {
          translation 0 0.2 0
          children [
            HingeJoint {
              jointParameters HingeJointParameters {
                position -19.18617703595865
                axis 0 1 0
              }
              device [
                RotationalMotor {
                  name "motor1"
                  maxVelocity 20
                }
                PositionSensor {
                  name "encoder1"
                }
              ]
              endPoint Solid {
                rotation -0.9723210594373679 0.165214340854347 -0.16521494772162146 4.6843197727706585
                children [
                  DEF ROUE_VISUEL Shape {
                    appearance Asphalt {
                    }
                    geometry Cylinder {
                      height 0.02
                      radius 0.03
                    }
                  }
                ]
                name "wheel_solid_1"
                boundingObject USE ROUE_VISUEL
                physics Physics {
                }
                linearVelocity -1.810575403690411e-13 -2.9384475830880565e-13 4.0434019322231935e-07
                angularVelocity 1.1799835315232005e-11 -7.308406899714194e-12 -2.1134120528992796e-13
              }
            }
          ]
        }
      ]
    }
    DEF WHEEL_B_WRAPPER Pose {
      rotation 0 0 1 1.0472
      children [
        DEF WHEEL_B_RADIUS Pose {
          translation 0 0.2 0
          children [
            HingeJoint {
              jointParameters HingeJointParameters {
                position 44.67768023820023
                axis 0 1 0
              }
              device [
                RotationalMotor {
                  name "motor2"
                  maxVelocity 20
                }
                PositionSensor {
                  name "encoder2"
                }
              ]
              endPoint Solid {
                rotation -0.8899221378756041 -0.3225196306820013 0.3225208153649304 4.596027483013335
                children [
                  USE ROUE_VISUEL
                ]
                name "wheel_solid_2"
                boundingObject USE ROUE_VISUEL
                physics Physics {
                }
                linearVelocity -2.9307997990156685e-13 -3.359305254597994e-14 4.04338940727719e-07
                angularVelocity -4.870817180238132e-13 -1.1234649605920978e-11 -2.1221622504996152e-13
              }
            }
          ]
        }
      ]
    }
    DEF WHEEL_C_WRAPPER Pose {
      rotation 0 0 1 3.14159
      children [
        DEF WHEEL_C_RADIUS Pose {
          translation 0 0.2 0
          children [
            HingeJoint {
              jointParameters HingeJointParameters {
                position 70.2135431728875
                axis 0 1 0
              }
              device [
                RotationalMotor {
                  name "motor3"
                  maxVelocity 20
                }
                PositionSensor {
                  name "encoder3"
                }
              ]
              endPoint Solid {
                rotation -0.7560858177724095 -0.462781083669117 0.46278278356207725 4.4363584553575475
                children [
                  USE ROUE_VISUEL
                ]
                name "wheel_solid_3"
                boundingObject USE ROUE_VISUEL
                physics Physics {
                }
                linearVelocity 2.6766922940644876e-14 -1.9035450935149272e-13 4.043377002956002e-07
                angularVelocity 6.0018955156197354e-12 3.4543887719218423e-12 -2.116969809115773e-13
              }
            }
          ]
        }
      ]
    }
  ]
  name "cdr"
  boundingObject USE CORPS_DEPLACE
  physics Physics {
    density -1
    mass 10
  }
  controller "<none>"
  linearVelocity -1.2060699817713025e-13 -1.3402670669890305e-13 -4.674090178014128e-10
  angularVelocity -1.7347678757720045e-13 1.280761204746269e-13 -2.1070730818067658e-13
}
