#VRML_SIM R2025a utf8
# license: Apache License 2.0
# license url: http://www.apache.org/licenses/LICENSE-2.0
# This is a proto file for Webots for the RobotOmniTriangle
# Extracted from: C:\robot_cdr\robot.urdf

PROTO RobotOmniTriangle [
  field  SFVec3f     translation     0 0 0
  field  SFRotation  rotation        0 0 1 0
  field  SFString    name            "RobotOmniTriangle"  # Is `Robot.name`.
  field  SFString    controller      "void"               # Is `Robot.controller`.
  field  MFString    controllerArgs  []                   # Is `Robot.controllerArgs`.
  field  SFString    customData      ""                   # Is `Robot.customData`.
  field  SFBool      supervisor      FALSE                # Is `Robot.supervisor`.
  field  SFBool      synchronization TRUE                 # Is `Robot.synchronization`.
  field  SFBool      selfCollision   FALSE                # Is `Robot.selfCollision`.
]
{
  Robot {
    translation IS translation
    rotation IS rotation
    controller IS controller
    controllerArgs IS controllerArgs
    customData IS customData
    supervisor IS supervisor
    synchronization IS synchronization
    selfCollision IS selfCollision
    children [
      Pose {
        rotation -1.000000 0.000000 0.000000 1.570796
        children [
          Shape {
            appearance DEF blue PBRAppearance {
              baseColor 0.200000 0.200000 0.800000
              roughness 1.000000
              metalness 0
            }
            geometry DEF base_link Mesh {
              url "..\..\robot_cdr\meshes\base_link.stl"
            }
          }
        ]
      }
      HingeJoint {
        jointParameters HingeJointParameters {
          axis 0.000000 1.000000 0.000000
          anchor 0.125000 0.000000 0.035000
        }
        device [
          RotationalMotor {
            name "joint_roue_1"
            maxTorque 10000
          }
          PositionSensor {
            name "joint_roue_1_sensor"
          }
        ]
        endPoint Solid {
          translation 0.125000 0.000000 0.035000
          children [
            Shape {
              appearance DEF black PBRAppearance {
                baseColor 0.100000 0.100000 0.100000
                roughness 1.000000
                metalness 0
              }
              geometry DEF roue Mesh {
                url "..\..\robot_cdr\meshes\roue.stl"
              }
            }
          ]
          name "roue_1"
          boundingObject Pose {
            rotation 1.000000 0.000000 0.000000 1.570796
            children [
              Cylinder {
                radius 0.03
                height 0.02
              }
            ]
          }
          physics Physics {
            density -1
            mass 0.200000
            centerOfMass [ 0.000000 0.000000 0.000000 ]
            inertiaMatrix [
              1.000000e-03 1.000000e-03 1.000000e-03
              0.000000e+00 0.000000e+00 0.000000e+00
            ]
          }
        }
      }
      HingeJoint {
        jointParameters HingeJointParameters {
          axis -0.866023 -0.500004 0.000000
          anchor -0.062500 0.108000 0.035000
        }
        device [
          RotationalMotor {
            name "joint_roue_2"
            maxTorque 10000
          }
          PositionSensor {
            name "joint_roue_2_sensor"
          }
        ]
        endPoint Solid {
          translation -0.062500 0.108000 0.035000
          rotation 0.000000 0.000000 1.000000 2.094400
          children [
            Shape {
              appearance USE black
              geometry USE roue
            }
          ]
          name "roue_2"
          boundingObject Pose {
            rotation 1.000000 0.000000 0.000000 1.570796
            children [
              Cylinder {
                radius 0.03
                height 0.02
              }
            ]
          }
          physics Physics {
            density -1
            mass 0.200000
            centerOfMass [ 0.000000 0.000000 0.000000 ]
            inertiaMatrix [
              1.000000e-03 1.000000e-03 1.000000e-03
              0.000000e+00 0.000000e+00 0.000000e+00
            ]
          }
        }
      }
      HingeJoint {
        jointParameters HingeJointParameters {
          axis 0.866023 -0.500004 0.000000
          anchor -0.062500 -0.108000 0.035000
        }
        device [
          RotationalMotor {
            name "joint_roue_3"
            maxTorque 10000
          }
          PositionSensor {
            name "joint_roue_3_sensor"
          }
        ]
        endPoint Solid {
          translation -0.062500 -0.108000 0.035000
          rotation 0.000000 0.000000 -1.000000 2.094400
          children [
            Shape {
              appearance USE black
              geometry USE roue
            }
          ]
          name "roue_3"
          boundingObject Pose {
            rotation 1.000000 0.000000 0.000000 1.570796
            children [
              Cylinder {
                radius 0.03
                height 0.02
              }
            ]
          }
          physics Physics {
            density -1
            mass 0.200000
            centerOfMass [ 0.000000 0.000000 0.000000 ]
            inertiaMatrix [
              1.000000e-03 1.000000e-03 1.000000e-03
              0.000000e+00 0.000000e+00 0.000000e+00
            ]
          }
        }
      }
    ]
    name IS name
    boundingObject Pose {
      translation 0.000000 0.000000 0.050000
      children [
        Box {
           size 0.400000 0.400000 0.100000
        }
      ]
    }
    physics Physics {
      density -1
      mass 5.000000
      centerOfMass [ 0.000000 0.000000 0.000000 ]
      inertiaMatrix [
        1.000000e-01 1.000000e-01 1.000000e-01
        0.000000e+00 0.000000e+00 0.000000e+00
      ]
    }
  }
}
