<?xml version="1.0" encoding="utf-8"?>
<robot name="Robot_Omni_Triangle">

  <link name="base_link">
    <visual>
      <origin xyz="0 0 0" rpy="-1.570796 0 0" />
      <geometry>
        <mesh filename="meshes/base_link.stl" />
      </geometry>
      <material name="blue">
        <color rgba="0.2 0.2 0.8 1.0"/>
      </material>
    </visual>
    
    <collision>
      <origin xyz="0 0 0.05" rpy="0 0 0" />
      <geometry>
        <box size="0.4 0.4 0.1"/> 
      </geometry>
    </collision>
    
    <inertial>
      <mass value="5.0"/>
      <inertia ixx="0.1" ixy="0" ixz="0" iyy="0.1" iyz="0" izz="0.1"/>
    </inertial>
  </link>

  <link name="roue_1">
    <visual>
      <origin xyz="0 0 0" rpy="0 0 0" />
      <geometry>
        <mesh filename="meshes/roue.stl" />
      </geometry>
      <material name="black"><color rgba="0.1 0.1 0.1 1.0"/></material>
    </visual>
    <collision>
      <origin xyz="0 0 0" rpy="1.570796 0 0" />
      <geometry>
        <cylinder radius="0.03" length="0.02"/>
      </geometry>
    </collision>
    <inertial>
      <mass value="0.2"/>
      <inertia ixx="0.001" ixy="0" ixz="0" iyy="0.001" iyz="0" izz="0.001"/>
    </inertial>
  </link>

  <link name="roue_2">
    <visual>
      <origin xyz="0 0 0" rpy="0 0 0" />
      <geometry><mesh filename="meshes/roue.stl" /></geometry>
      <material name="black"/>
    </visual>
    <collision>
      <origin xyz="0 0 0" rpy="1.570796 0 0" />
      <geometry><cylinder radius="0.03" length="0.02"/></geometry>
    </collision>
    <inertial>
      <mass value="0.2"/>
      <inertia ixx="0.001" ixy="0" ixz="0" iyy="0.001" iyz="0" izz="0.001"/>
    </inertial>
  </link>

  <link name="roue_3">
    <visual>
      <origin xyz="0 0 0" rpy="0 0 0" />
      <geometry><mesh filename="meshes/roue.stl" /></geometry>
      <material name="black"/>
    </visual>
    <collision>
      <origin xyz="0 0 0" rpy="1.570796 0 0" />
      <geometry><cylinder radius="0.03" length="0.02"/></geometry>
    </collision>
    <inertial>
      <mass value="0.2"/>
      <inertia ixx="0.001" ixy="0" ixz="0" iyy="0.001" iyz="0" izz="0.001"/>
    </inertial>
  </link>


  <joint name="joint_roue_1" type="continuous">
    <parent link="base_link"/>
    <child link="roue_1"/>
    <origin xyz="0.125 0 0.035" rpy="0 0 0" />
    <axis xyz="0 1 0" />
  </joint>

  <joint name="joint_roue_2" type="continuous">
    <parent link="base_link"/>
    <child link="roue_2"/>
    <origin xyz="-0.0625 0.108 0.035" rpy="0 0 2.0944" />
    <axis xyz="0 1 0" />
  </joint>

  <joint name="joint_roue_3" type="continuous">
    <parent link="base_link"/>
    <child link="roue_3"/>
    <origin xyz="-0.0625 -0.108 0.035" rpy="0 0 -2.0944" />
    <axis xyz="0 1 0" />
  </joint>

</robot>